## Кратко:

При перехвате всех исключений в C++ с помощью `catch (...)` следует учитывать некоторые рекомендации для правильного расположения и обработки неожиданных ситуаций.

---

## Рекомендации по расположению и обработке

1. **Последний блок `catch`**
   - **Расположение**: Блок `catch (...)` должен располагаться последним в цепочке `catch` блоков.
   - **Причина**: Это позволяет перехватывать все исключения, которые не были обработаны в предыдущих блоках `catch`. Такой подход является последней линией обороны для обработки неожиданных исключений.

2. **Общее сообщение**
   - **Сообщение**: В блоке `catch (...)` рекомендуется выводить общее сообщение о неизвестной ошибке или неспецифицированной исключительной ситуации.
   - **Пример**: `"Unknown exception occurred"` или аналогичное сообщение помогает идентифицировать места, где произошли необработанные исключения.

3. **Осторожность с ресурсами**
   - **Освобождение ресурсов**: При использовании `catch (...)` следует быть осторожным с освобождением ресурсов, так как это блок не может предсказать, какое исключение произойдет.
   - **Пример**: Если вам нужно освободить ресурсы, которые могут находиться в нестабильном состоянии из-за исключения, это можно сделать в блоке `catch (...)`, но лучше всего использовать конструкторы для управления ресурсами.

## Пример использования `catch (...)`

```cpp
#include <iostream>
#include <stdexcept>

void process(int value) {
    if (value == 0) {
        throw std::invalid_argument("Value cannot be zero");
    } else if (value < 0) {
        throw std::runtime_error("Negative value encountered");
    }
    std::cout << "Processed value: " << value << std::endl;
}

int main() {
    try {
        process(-5); // Генерирует std::runtime_error
        process(0);  // Генерирует std::invalid_argument
        process(10); // Проходит без исключений
    } catch (const std::invalid_argument& e) {
        std::cerr << "Invalid argument exception: " << e.what() << std::endl;
    } catch (const std::runtime_error& e) {
        std::cerr << "Runtime error exception: " << e.what() << std::endl;
    } catch (...) {
        std::cerr << "Unknown exception occurred" << std::endl;
    }

    return 0;
}
```

В этом примере:

- Функция `process` может генерировать два разных типа исключений в зависимости от переданного значения.
- Блок `catch (...)` перехватывает все остальные типы исключений, которые не были перехвачены в более специфических блоках `catch`.
- В блоке `catch (...)` выводится общее сообщение об ошибке, указывающее на неожиданную ситуацию.
